Workbook

Sheet Lisez-moi
A1: Achats n3-universal — 4 projets
A2: Carte universelle rev 0.2.2 (hardware/n3-universal). Prix relevés le 18/10/2026 chez les boutiques marocaines en ligne.
A4: Feuilles
A5: Global — tout ce qu'il faut acheter pour les 4 unités, rechange comprise, arrondi aux lots vendus, avec le coût total.
A6: msp1, n3pp, ffp5cs 230V, ffp5cs 12V — une feuille par projet : consignes de pose, composants à poser sur la carte et ce qui se branche autour, coût d'une unité.
A7: Prix — catalogue unique (fournisseur, prix, lien). Changer un prix ici met tout le classeur à jour.
A9: Cellules modifiables (texte bleu)
A10: Qté dans les feuilles projet ; Rechange dans Global ; Prix du lot et Taille du lot dans Prix. Le reste est calculé.
A12: Statuts et couleurs
A13: À acheter — compté dans les totaux. Fond rose = introuvable au Maroc, à mettre dans le colis LCSC combiné avec la commande JLCPCB (COMMANDE.md §2).
A14: Option — fond jaune : utile mais pas indispensable (BME280, INA226 supplémentaires, microSD). Total séparé.
A15: Déjà possédé — fond vert : TP4056, batterie AGM, régulateur PWM, panneau 12 V. Valeur indicative, hors total.
... A32: Prix tels qu'affichés au relevé ; stocks variables (plusieurs articles en rupture, signalés). Certains prix viennent d'une fourchette de variantes (bas de fourchette retenu) : à confirmer au panier. Les quantités de câble et de presse-étoupes sont des estimations à ajuster à l'installation.

Sheet Global
A1: Liste globale d'achats — 4 unités n3-universal (msp1, n3pp, ffp5cs 230 V, ffp5cs 12 V)
A2: Quantités tirées des feuilles projet (formules) + rechange conseillée (bleu, modifiable), arrondies aux lots vendus par les boutiques. Prix du 18/10/2026, feuille Prix.
C4: Total à acheter, 4 unités, arrondi aux lots (DH) | O4: =SUMIFS(O15:O87,D15:D87,"À acheter")+SUM(O91:O93) -> 5459.5
C5: dont outillage et consommables partagés (DH) | O5: =SUM(O91:O93) -> 674
C6: Options, si toutes prises (DH) | O6: =SUMIFS(O15:O87,D15:D87,"Option") -> 373
C7: Déjà possédé — valeur indicative (DH) | O7: =SUMIFS(O15:O87,D15:D87,"Déjà possédé") -> 983
C8: Lignes à acheter sans prix en ligne (import LCSC, quincaillerie, PCB) | O8: =SUMPRODUCT((D15:D87="À acheter")*(K15:K87>0)*(N15:N87="")) -> 5
C10: Coût d'UNE unité (à l'unité, sans arrondi aux lots) | E10: msp1 | F10: n3pp | G10: ffp5cs 230V | H10: ffp5cs 12V
C11: À acheter (DH) | E11: =msp1!J11 -> 1072.1 | F11: =n3pp!J11 -> 929.8 | G11: ='ffp5cs 230V'!J11 -> 1199.6 | H11: ='ffp5cs 12V'!J11 -> 1189.4
C12: Options (DH) | E12: =msp1!J12 -> 170 | F12: =n3pp!J12 -> 85 | G12: ='ffp5cs 230V'!J12 -> 18 | H12: ='ffp5cs 12V'!J12 -> 100
A14: ID | B14: Catégorie | C14: Article | D14: Statut | E14: msp1 | F14: n3pp | G14: ffp5cs 230V | H14: ffp5cs 12V | I14: Total 4 unités | J14: Rechange | K14: Qté à acheter | L14: Taille du lot | M14: Nb de lots | N14: Prix du lot (DH) | O14: Coût (DH) | P14: Fournisseur | Q14: Source | R14: Remarque achat | S14: Lien
A15: PCB | B15: 1. Carte et cerveau | C15: Circuit imprimé n3-universal rev 0.2.2 (JLCPCB, 2 oz) | D15: À acheter | E15: =SUMIFS(msp1!$F:$F,msp1!$A:$A,$A15,msp1!$G:$G,$D15) -> 1 | F15: =SUMIFS(n3pp!$F:$F,n3pp!$A:$A,$A15,n3pp!$G:$G,$D15) -> 1 | G15: =SUMIFS('ffp5cs 230V'!$F:$F,'ffp5cs 230V'!$A:$A,$A15,'ffp5cs 230V'!$G:$G,$D15) -> 1 | H15: =SUMIFS('ffp5cs 12V'!$F:$F,'ffp5cs 12V'!$A:$A,$A15,'ffp5cs 12V'!$G:$G,$D15) -> 1 | I15: =SUM(E15:H15) -> 4 | J15: 0 | K15: =IF(I15=0,0,I15+J15) -> 4 | L15: =INDEX(Prix!$E$5:$E$79,MATCH($A15,Prix!$A$5:$A$79,0)) -> 1 | M15: =IF(K15=0,0,ROUNDUP(K15/L15,0)) -> 4 | N15: =IF(INDEX(Prix!$D$5:$D$79,MATCH($A15,Prix!$A$5:$A$79,0))="","",INDEX(Prix!$D$5:$D$79,MATCH($A15,Prix!$A$5:$A$79,0))) | O15: =IF(N15="","",M15*N15) | P15: =INDEX(Prix!$C$5:$C$79,MATCH($A15,Prix!$A$5:$A$79,0)) -> JLCPCB | Q15: =INDEX(Prix!$H$5:$H$79,MATCH($A15,Prix!$A$5:$A$79,0)) -> Import | R15: Commande unique de 10 cartes : ≈ 55–85 $ les 5 + port (COMMANDE.md) ; prix réel au devis JLCPCB. | S15: lien
A16: ESP32_DEVKIT | B16: 1. Carte et cerveau | C16: ESP32 DevKit V1 30 broches (WROOM-32) | D16: À acheter | E16: =SUMIFS(msp1!$F:$F,msp1!$A:$A,$A16,msp1!$G:$G,$D16) -> 1 | F16: =SUMIFS(n3pp!$F:$F,n3pp!$A:$A,$A16,n3pp!$G:$G,$D16) -> 1 | G16: =SUMIFS('ffp5cs 230V'!$F:$F,'ffp5cs 230V'!$A:$A,$A16,'ffp5cs 230V'!$G:$G,$D16) -> 1 | H16: =SUMIFS('ffp5cs 12V'!$F:$F,'ffp5cs 12V'!$A:$A,$A16,'ffp5cs 12V'!$G:$G,$D16) -> 1 | I16: =SUM(E16:H16) -> 4 | J16: 1 | K16: =IF(I16=0,0,I16+J16) -> 5 | L16: =INDEX(Prix!$E$5:$E$79,MATCH($A16,Prix!$A$5:$A$79,0)) -> 1 | M16: =IF(K16=0,0,ROUNDUP(K16/L16,0)) -> 5 | N16: =IF(INDEX(Prix!$D$5:$D$79,MATCH($A16,Prix!$A$5:$A$79,0))="","",INDEX(Prix!$D$5:$D$79,MATCH($A16,Prix!$A$5:$A$79,0))) -> 113 | O16: =IF(N16="","",M16*N16) -> 565 | P16: =INDEX(Prix!$C$5:$C$79,MATCH($A16,Prix!$A$5:$A$79,0)) -> Shop4Makers | Q16: =INDEX(Prix!$H$5:$H$79,MATCH($A16,Prix!$A$5:$A$79,0)) -> Maroc | R16: ESP32 WROOM CP2102 30 broches. Ne pas importer (ANRT). Repli A2itronic 120 DH. | S16: lien
A17: R_220 | B17: 2. Résistances | C17: Résistance 220 Ω 1/4 W | D17: À acheter | E17: =SUMIFS(msp1!$F:$F,msp1!$A:$A,$A17,msp1!$G:$G,$D17) -> 2 | F17: =SUMIFS(n3pp!$F:$F,n3pp!$A:$A,$A17,n3pp!$G:$G,$D17) -> 0 | G17: =SUMIFS('ffp5cs 230V'!$F:$F,'ffp5cs 230V'!$A:$A,$A17,'ffp5cs 230V'!$G:$G,$D17) -> 2 | H17: =SUMIFS('ffp5cs 12V'!$F:$F,'ffp5cs 12V'!$A:$A,$A17,'ffp5cs 12V'!$G:$G,$D17) -> 2 | I17: =SUM(E17:H17) -> 6 | J17: 2 | K17: =IF(I17=0,0,I17+J17) -> 8 | L17: =INDEX(Prix!$E$5:$E$79,MATCH($A17,Prix!$A$5:$A$79,0)) -> 5 | M17: =IF(K17=0,0,ROUNDUP(K17/L17,0)) -> 2 | N17: =IF(INDEX(Prix!$D$5:$D$79,MATCH($A17,Prix!$A$5:$A$79,0))="","",INDEX(Prix!$D$5:$D$79,MATCH($A17,Prix!$A$5:$A$79,0))) -> 1.5 | O17: =IF(N17="","",M17*N17) -> 3 | P17: =INDEX(Prix!$C$5:$C$79,MATCH($A17,Prix!$A$5:$A$79,0)) -> MicroPlanet | Q17: =INDEX(Prix!$H$5:$H$79,MATCH($A17,Prix!$A$5:$A$79,0)) -> Maroc | R17: 1/4 W 1 %, vendues par 5. | S17: lien
A18: R_1k | B18: 2. Résistances | C18: Résistance 1 kΩ 1/4 W | D18: À acheter | E18: =SUMIFS(msp1!$F:$F,msp1!$A:$A,$A18,msp1!$G:$G,$D18) -> 7 | F18: =SUMIFS(n3pp!$F:$F,n3pp!$A:$A,$A18,n3pp!$G:$G,$D18) -> 10 | G18: =SUMIFS('ffp5cs 230V'!$F:$F,'ffp5cs 230V'!$A:$A,$A18,'ffp5cs 230V'!$G:$G,$D18) -> 23 | H18: =SUMIFS('ffp5cs 12V'!$F:$F,'ffp5cs 12V'!$A:$A,$A18,'ffp5cs 12V'!$G:$G,$D18) -> 24 | I18: =SUM(E18:H18) -> 64 | J18: 5 | K18: =IF(I18=0,0,I18+J18) -> 69 | L18: =INDEX(Prix!$E$5:$E$79,MATCH($A18,Prix!$A$5:$A$79,0)) -> 5 | M18: =IF(K18=0,0,ROUNDUP(K18/L18,0)) -> 14 | N18: =IF(INDEX(Prix!$D$5:$D$79,MATCH($A18,Prix!$A$5:$A$79,0))="","",INDEX(Prix!$D$5:$D$79,MATCH($A18,Prix!$A$5:$A$79,0))) -> 1.5 | O18: =IF(N18="","",M18*N18) -> 21 | P18: =INDEX(Prix!$C$5:$C$79,MATCH($A18,Prix!$A$5:$A$79,0)) -> MicroPlanet | Q18: =INDEX(Prix!$H$5:$H$79,MATCH($A18,Prix!$A$5:$A$79,0)) -> Maroc | R18: 1/4 W 1 %, vendues par 5. | S18: lien
A19: R_2k | B19: 2. Résistances | C19: Résistance 2 kΩ 1/4 W (2,2 kΩ convient) | D19: À acheter | E19: =SUMIFS(msp1!$F:$F,msp1!$A:$A,$A19,msp1!$G:$G,$D19) -> 0 | F19: =SUMIFS(n3pp!$F:$F,n3pp!$A:$A,$A19,n3pp!$G:$G,$D19) -> 0 | G19: =SUMIFS('ffp5cs 230V'!$F:$F,'ffp5cs 230V'!$A:$A,$A19,'ffp5cs 230V'!$G:$G,$D19) -> 3 | H19: =SUMIFS('ffp5cs 12V'!$F:$F,'ffp5cs 12V'!$A:$A,$A19,'ffp5cs 12V'!$G:$G,$D19) -> 3 | I19: =SUM(E19:H19) -> 6 | J19: 2 | K19: =IF(I19=0,0,I19+J19) -> 8 | L19: =INDEX(Prix!$E$5:$E$79,MATCH($A19,Prix!$A$5:$A$79,0)) -> 5 | M19: =IF(K19=0,0,ROUNDUP(K19/L19,0)) -> 2 | N19: =IF(INDEX(Prix!$D$5:$D$79,MATCH($A19,Prix!$A$5:$A$79,0))="","",INDEX(Prix!$D$5:$D$79,MATCH($A19,Prix!$A$5:$A$79,0))) -> 1.5 | O19: =IF(N19="","",M19*N19) -> 3 | P19: =INDEX(Prix!$C$5:$C$79,MATCH($A19,Prix!$A$5:$A$79,0)) -> MicroPlanet | Q19: =INDEX(Prix!$H$5:$H$79,MATCH($A19,Prix!$A$5:$A$79,0)) -> Maroc | R19: 1/4 W 1 %, vendues par 5. | S19: lien
A20: R_4.7k | B20: 2. Résistances | C20: Résistance 4,7 kΩ 1/4 W | D20: À acheter | E20: =SUMIFS(msp1!$F:$F,msp1!$A:$A,$A20,msp1!$G:$G,$D20) -> 3 | F20: =SUMIFS(n3pp!$F:$F,n3pp!$A:$A,$A20,n3pp!$G:$G,$D20) -> 2 | G20: =SUMIFS('ffp5cs 230V'!$F:$F,'ffp5cs 230V'!$A:$A,$A20,'ffp5cs 230V'!$G:$G,$D20) -> 3 | H20: =SUMIFS('ffp5cs 12V'!$F:$F,'ffp5cs 12V'!$A:$A,$A20,'ffp5cs 12V'!$G:$G,$D20) -> 3 | I20: =SUM(E20:H20) -> 11 | J20: 2 | K20: =IF(I20=0,0,I20+J20) -> 13 | L20: =INDEX(Prix!$E$5:$E$79,MATCH($A20,Prix!$A$5:$A$79,0)) -> 5 | M20: =IF(K20=0,0,ROUNDUP(K20/L20,0)) -> 3 | N20: =IF(INDEX(Prix!$D$5:$D$79,MATCH($A20,Prix!$A$5:$A$79,0))="","",INDEX(Prix!$D$5:$D$79,MATCH($A20,Prix!$A$5:$A$79,0))) -> 1.5 | O20: =IF(N20="","",M20*N20) -> 4.5 | P20: =INDEX(Prix!$C$5:$C$79,MATCH($A20,Prix!$A$5:$A$79,0)) -> MicroPlanet | Q20: =INDEX(Prix!$H$5:$H$79,MATCH($A20,Prix!$A$5:$A$79,0)) -> Maroc | R20: 1/4 W 1 %, vendues par 5. | S20: lien
A21: R_10k | B21: 2. Résistances | C21: Résistance 10 kΩ 1/4 W | D21: À acheter | E21: =SUMIFS(msp1!$F:$F,msp1!$A:$A,$A21,msp1!$G:$G,$D21) -> 7 | F21: =SUMIFS(n3pp!$F:$F,n3pp!$A:$A,$A21,n3pp!$G:$G,$D21) -> 4 | G21: =SUMIFS('ffp5cs 230V'!$F:$F,'ffp5cs 230V'!$A:$A,$A21,'ffp5cs 230V'!$G:$G,$D21) -> 9 | H21: =SUMIFS('ffp5cs 12V'!$F:$F,'ffp5cs 12V'!$A:$A,$A21,'ffp5cs 12V'!$G:$G,$D21) -> 9 | I21: =SUM(E21:H21) -> 29 | J21: 5 | K21: =IF(I21=0,0,I21+J21) -> 34 | L21: =INDEX(Prix!$E$5:$E$79,MATCH($A21,Prix!$A$5:$A$79,0)) -> 5 | M21: =IF(K21=0,0,ROUNDUP(K21/L21,0)) -> 7 | N21: =IF(INDEX(Prix!$D$5:$D$79,MATCH($A21,Prix!$A$5:$A$79,0))="","",INDEX(Prix!$D$5:$D$79,MATCH($A21,Prix!$A$5:$A$79,0))) -> 1.5 | O21: =IF(N21="","",M21*N21) -> 10.5 | P21: =INDEX(Prix!$C$5:$C$79,MATCH($A21,Prix!$A$5:$A$79,0)) -> MicroPlanet | Q21: =INDEX(Prix!$H$5:$H$79,MATCH($A21,Prix!$A$5:$A$79,0)) -> Maroc | R21: 1/4 W 1 %, vendues par 5. | S21: lien
A22: R_18k | B22: 2. Résistances | C22: Résistance 18 kΩ 1/4 W | D22: À acheter | E22: =SUMIFS(msp1!$F:$F,msp1!$A:$A,$A22,msp1!$G:$G,$D22) -> 1 | F22: =SUMIFS(n3pp!$F:$F,n3pp!$A:$A,$A22,n3pp!$G:$G,$D22) -> 1 | G22: =SUMIFS('ffp5cs 230V'!$F:$F,'ffp5cs 230V'!$A:$A,$A22,'ffp5cs 230V'!$G:$G,$D22) -> 0 | H22: =SUMIFS('ffp5cs 12V'!$F:$F,'ffp5cs 12V'!$A:$A,$A22,'ffp5cs 12V'!$G:$G,$D22) -> 1 | I22: =SUM(E22:H22) -> 3 | J22: 2 | K22: =IF(I22=0,0,I22+J22) -> 5 | L22: =INDEX(Prix!$E$5:$E$79,MATCH($A22,Prix!$A$5:$A$79,0)) -> 5 | M22: =IF(K22=0,0,ROUNDUP(K22/L22,0)) -> 1 | N22: =IF(INDEX(Prix!$D$5:$D$79,MATCH($A22,Prix!$A$5:$A$79,0))="","",INDEX(Prix!$D$5:$D$79,MATCH($A22,Prix!$A$5:$A$79,0))) -> 1.5 | O22: =IF(N22="","",M22*N22) -> 1.5 | P22: =INDEX(Prix!$C$5:$C$79,MATCH($A22,Prix!$A$5:$A$79,0)) -> MicroPlanet | Q22: =INDEX(Prix!$H$5:$H$79,MATCH($A22,Prix!$A$5:$A$79,0)) -> Maroc | R22: 1/4 W 1 %, vendues par 5. | S22: lien
A23: R_100k | B23: 2. Résistances | C23: Résistance 100 kΩ 1/4 W | D23: À acheter | E23: =SUMIFS(msp1!$F:$F,msp1!$A:$A,$A23,msp1!$G:$G,$D23) -> 4 | F23: =SUMIFS(n3pp!$F:$F,n3pp!$A:$A,$A23,n3pp!$G:$G,$D23) -> 4 | G23: =SUMIFS('ffp5cs 230V'!$F:$F,'ffp5cs 230V'!$A:$A,$A23,'ffp5cs 230V'!$G:$G,$D23) -> 2 | H23: =SUMIFS('ffp5cs 12V'!$F:$F,'ffp5cs 12V'!$A:$A,$A23,'ffp5cs 12V'!$G:$G,$D23) -> 5 | I23: =SUM(E23:H23) -> 15 | J23: 3 | K23: =IF(I23=0,0,I23+J23) -> 18 | L23: =INDEX(Prix!$E$5:$E$79,MATCH($A23,Prix!$A$5:$A$79,0)) -> 5 | M23: =IF(K23=0,0,ROUNDUP(K23/L23,0)) -> 4 | N23: =IF(INDEX(Prix!$D$5:$D$79,MATCH($A23,Prix!$A$5:$A$79,0))="","",INDEX(Prix!$D$5:$D$79,MATCH($A23,Prix!$A$5:$A$79,0))) -> 1.5 | O23: =IF(N23="","",M23*N23) -> 6 | P23: =INDEX(Prix!$C$5:$C$79,MATCH($A23,Prix!$A$5:$A$79,0)) -> MicroPlanet | Q23: =INDEX(Prix!$H$5:$H$79,MATCH($A23,Prix!$A$5:$A$79,0)) -> Maroc | R23: 1/4 W 1 %, vendues par 5. | S23: lien
A24: C_100n | B24: 3. Condensateurs | C24: Condensateur céramique 100 nF (pas 5 mm) | D24: À acheter | E24: =SUMIFS(msp1!$F:$F,msp1!$A:$A,$A24,msp1!$G:$G,$D24) -> 8 | F24: =SUMIFS(n3pp!$F:$F,n3pp!$A:$A,$A24,n3pp!$G:$G,$D24) -> 8 | G24: =SUMIFS('ffp5cs 230V'!$F:$F,'ffp5cs 230V'!$A:$A,$A24,'ffp5cs 230V'!$G:$G,$D24) -> 3 | H24: =SUMIFS('ffp5cs 12V'!$F:$F,'ffp5cs 12V'!$A:$A,$A24,'ffp5cs 12V'!$G:$G,$D24) -> 4 | I24: =SUM(E24:H24) -> 23 | J24: 5 | K24: =IF(I24=0,0,I24+J24) -> 28 | L24: =INDEX(Prix!$E$5:$E$79,MATCH($A24,Prix!$A$5:$A$79,0)) -> 1 | M24: =IF(K24=0,0,ROUNDUP(K24/L24,0)) -> 28 | N24: =IF(INDEX(Prix!$D$5:$D$79,MATCH($A24,Prix!$A$5:$A$79,0))="","",INDEX(Prix!$D$5:$D$79,MATCH($A24,Prix!$A$5:$A$79,0))) -> 0.5 | O24: =IF(N24="","",M24*N24) -> 14 | P24: =INDEX(Prix!$C$5:$C$79,MATCH($A24,Prix!$A$5:$A$79,0)) -> A2itronic | Q24: =INDEX(Prix!$H$5:$H$79,MATCH($A24,Prix!$A$5:$A$79,0)) -> Maroc | R24: Céramique 50 V. | S24: lien
A25: C_10u25 | B25: 3. Condensateurs | C25: Condensateur électrolytique 10 µF 25 V | D25: À acheter | E25: =SUMIFS(msp1!$F:$F,msp1!$A:$A,$A25,msp1!$G:$G,$D25) -> 1 | F25: =SUMIFS(n3pp!$F:$F,n3pp!$A:$A,$A25,n3pp!$G:$G,$D25) -> 1 | G25: =SUMIFS('ffp5cs 230V'!$F:$F,'ffp5cs 230V'!$A:$A,$A25,'ffp5cs 230V'!$G:$G,$D25) -> 1 | H25: =SUMIFS('ffp5cs 12V'!$F:$F,'ffp5cs 12V'!$A:$A,$A25,'ffp5cs 12V'!$G:$G,$D25) -> 1 | I25: =SUM(E25:H25) -> 4 | J25: 1 | K25: =IF(I25=0,0,I25+J25) -> 5 | L25: =INDEX(Prix!$E$5:$E$79,MATCH($A25,Prix!$A$5:$A$79,0)) -> 1 | M25: =IF(K25=0,0,ROUNDUP(K25/L25,0)) -> 5 | N25: =IF(INDEX(Prix!$D$5:$D$79,MATCH($A25,Prix!$A$5:$A$79,0))="","",INDEX(Prix!$D$5:$D$79,MATCH($A25,Prix!$A$5:$A$79,0))) -> 1 | O25: =IF(N25="","",M25*N25) -> 5 | P25: =INDEX(Prix!$C$5:$C$79,MATCH($A25,Prix!$A$5:$A$79,0)) -> A2itronic | Q25: =INDEX(Prix!$H$5:$H$79,MATCH($A25,Prix!$A$5:$A$79,0)) -> Maroc | R25: Proposé en 50 V (mieux que 25 V). | S25: lien
A26: C_100u16 | B26: 3. Condensateurs | C26: Condensateur électrolytique 100 µF 16 V | D26: À acheter | E26: =SUMIFS(msp1!$F:$F,msp1!$A:$A,$A26,msp1!$G:$G,$D26) -> 1 | F26: =SUMIFS(n3pp!$F:$F,n3pp!$A:$A,$A26,n3pp!$G:$G,$D26) -> 1 | G26: =SUMIFS('ffp5cs 230V'!$F:$F,'ffp5cs 230V'!$A:$A,$A26,'ffp5cs 230V'!$G:$G,$D26) -> 1 | H26: =SUMIFS('ffp5cs 12V'!$F:$F,'ffp5cs 12V'!$A:$A,$A26,'ffp5cs 12V'!$G:$G,$D26) -> 1 | I26: =SUM(E26:H26) -> 4 | J26: 1 | K26: =IF(I26=0,0,I26+J26) -> 5 | L26: =INDEX(Prix!$E$5:$E$79,MATCH($A26,Prix!$A$5:$A$79,0)) -> 1 | M26: =IF(K26=0,0,ROUNDUP(K26/L26,0)) -> 5 | N26: =IF(INDEX(Prix!$D$5:$D$79,MATCH($A26,Prix!$A$5:$A$79,0))="","",INDEX(Prix!$D$5:$D$79,MATCH($A26,Prix!$A$5:$A$79,0))) -> 1 | O26: =IF(N26="","",M26*N26) -> 5 | P26: =INDEX(Prix!$C$5:$C$79,MATCH($A26,Prix!$A$5:$A$79,0)) -> A2itronic | Q26: =INDEX(Prix!$H$5:$H$79,MATCH($A26,Prix!$A$5:$A$79,0)) -> Maroc | R26: 5×7 mm. | S26: lien
... A29: C_1000u16 | B29: 3. Condensateurs | C29: Condensateur électrolytique 1000 µF 16 V (diam. 10 mm) | D29: À acheter | E29: =SUMIFS(msp1!$F:$F,msp1!$A:$A,$A29,msp1!$G:$G,$D29) -> 1 | F29: =SUMIFS(n3pp!$F:$F,n3pp!$A:$A,$A29,n3pp!$G:$G,$D29) -> 1 | G29: =SUMIFS('ffp5cs 230V'!$F:$F,'ffp5cs 230V'!$A:$A,$A29,'ffp5cs 230V'!$G:$G,$D29) -> 1 | H29: =SUMIFS('ffp5cs 12V'!$F:$F,'ffp5cs 12V'!$A:$A,$A29,'ffp5cs 12V'!$G:$G,$D29) -> 1 | I29: =SUM(E29:H29) -> 4 | J29: 1 | K29: =IF(I29=0,0,I29+J29) -> 5 | L29: =INDEX(Prix!$E$5:$E$79,MATCH($A29,Prix!$A$5:$A$79,0)) -> 1 | M29: =IF(K29=0,0,ROUNDUP(K29/L29,0)) -> 5 | N29: =IF(INDEX(Prix!$D$5:$D$79,MATCH($A29,Prix!$A$5:$A$79,0))="","",INDEX(Prix!$D$5:$D$79,MATCH($A29,Prix!$A$5:$A$79,0))) -> 3 | O29: =IF(N29="","",M29*N29) -> 15 | P29: =INDEX(Prix!$C$5:$C$79,MATCH($A29,Prix!$A$5:$A$79,0)) -> A2itronic | Q29: =INDEX(Prix!$H$5:$H$79,MATCH($A29,Prix!$A$5:$A$79,0)) -> Maroc | R29: Page ambiguë 16/25 V : les deux conviennent, mais diamètre ≤ 10 mm et pas 5 mm. | S29: lien
A30: 1N4007 | B30: 4. Semi-conducteurs | C30: Diode 1N4007 (roue libre des bobines de relais) | D30: À acheter | E30: =SUMIFS(msp1!$F:$F,msp1!$A:$A,$A30,msp1!$G:$G,$D30) -> 0 | F30: =SUMIFS(n3pp!$F:$F,n3pp!$A:$A,$A30,n3pp!$G:$G,$D30) -> 1 | G30: =SUMIFS('ffp5cs 230V'!$F:$F,'ffp5cs 230V'!$A:$A,$A30,'ffp5cs 230V'!$G:$G,$D30) -> 6 | H30: =SUMIFS('ffp5cs 12V'!$F:$F,'ffp5cs 12V'!$A:$A,$A30,'ffp5cs 12V'!$G:$G,$D30) -> 6 | I30: =SUM(E30:H30) -> 13 | J30: 3 | K30: =IF(I30=0,0,I30+J30) -> 16 | L30: =INDEX(Prix!$E$5:$E$79,MATCH($A30,Prix!$A$5:$A$79,0)) -> 1 | M30: =IF(K30=0,0,ROUNDUP(K30/L30,0)) -> 16 | N30: =IF(INDEX(Prix!$D$5:$D$79,MATCH($A30,Prix!$A$5:$A$79,0))="","",INDEX(Prix!$D$5:$D$79,MATCH($A30,Prix!$A$5:$A$79,0))) -> 0.9 | O30: =IF(N30="","",M30*N30) -> 14.4 | P30: =INDEX(Prix!$C$5:$C$79,MATCH($A30,Prix!$A$5:$A$79,0)) -> Shop4Makers | Q30: =INDEX(Prix!$H$5:$H$79,MATCH($A30,Prix!$A$5:$A$79,0)) -> Maroc | S30: lien
A31: BAT85 | B31: 4. Semi-conducteurs | C31: Diode Schottky BAT85 / BAT43 / BAT42 (DO-35) | D31: À acheter | E31: =SUMIFS(msp1!$F:$F,msp1!$A:$A,$A31,msp1!$G:$G,$D31) -> 1 | F31: =SUMIFS(n3pp!$F:$F,n3pp!$A:$A,$A31,n3pp!$G:$G,$D31) -> 1 | G31: =SUMIFS('ffp5cs 230V'!$F:$F,'ffp5cs 230V'!$A:$A,$A31,'ffp5cs 230V'!$G:$G,$D31) -> 0 | H31: =SUMIFS('ffp5cs 12V'!$F:$F,'ffp5cs 12V'!$A:$A,$A31,'ffp5cs 12V'!$G:$G,$D31) -> 1 | I31: =SUM(E31:H31) -> 3 | J31: 1 | K31: =IF(I31=0,0,I31+J31) -> 4 | L31: =INDEX(Prix!$E$5:$E$79,MATCH($A31,Prix!$A$5:$A$79,0)) -> 1 | M31: =IF(K31=0,0,ROUNDUP(K31/L31,0)) -> 4 | N31: =IF(INDEX(Prix!$D$5:$D$79,MATCH($A31,Prix!$A$5:$A$79,0))="","",INDEX(Prix!$D$5:$D$79,MATCH($A31,Prix!$A$5:$A$79,0))) -> 2 | O31: =IF(N31="","",M31*N31) -> 8 | P31: =INDEX(Prix!$C$5:$C$79,MATCH($A31,Prix!$A$5:$A$79,0)) -> Moussasoft | Q31: =INDEX(Prix!$H$5:$H$79,MATCH($A31,Prix!$A$5:$A$79,0)) -> Maroc | R31: Boîtier DO-34, se pose sur les trous DO-35. BAT43/42/54 introuvables au Maroc. | S31: lien
A32: TVS_6V8 | B32: 4. Semi-conducteurs | C32: Diode TVS 1.5KE6.8A (ou P6KE6.8A) | D32: À acheter | E32: =SUMIFS(msp1!$F:$F,msp1!$A:$A,$A32,msp1!$G:$G,$D32) -> 1 | F32: =SUMIFS(n3pp!$F:$F,n3pp!$A:$A,$A32,n3pp!$G:$G,$D32) -> 1 | G32: =SUMIFS('ffp5cs 230V'!$F:$F,'ffp5cs 230V'!$A:$A,$A32,'ffp5cs 230V'!$G:$G,$D32) -> 1 | H32: =SUMIFS('ffp5cs 12V'!$F:$F,'ffp5cs 12V'!$A:$A,$A32,'ffp5cs 12V'!$G:$G,$D32) -> 1 | I32: =SUM(E32:H32) -> 4 | J32: 1 | K32: =IF(I32=0,0,I32+J32) -> 5 | L32: =INDEX(Prix!$E$5:$E$79,MATCH($A32,Prix!$A$5:$A$79,0)) -> 1 | M32: =IF(K32=0,0,ROUNDUP(K32/L32,0)) -> 5 | N32: =IF(INDEX(Prix!$D$5:$D$79,MATCH($A32,Prix!$A$5:$A$79,0))="","",INDEX(Prix!$D$5:$D$79,MATCH($A32,Prix!$A$5:$A$79,0))) | O32: =IF(N32="","",M32*N32) | P32: =INDEX(Prix!$C$5:$C$79,MATCH($A32,Prix!$A$5:$A$79,0)) -> LCSC | Q32: =INDEX(Prix!$H$5:$H$79,MATCH($A32,Prix!$A$5:$A$79,0)) -> Import LCSC | R32: Introuvable au Maroc : LCSC C412500 (repli P6KE6.8A C409413), colis combiné JLCPCB. | S32: lien
A33: TVS_18 | B33: 4. Semi-conducteurs | C33: Diode TVS 1.5KE18A (ou P6KE18A) — PAS 15 V | D33: À acheter | E33: =SUMIFS(msp1!$F:$F,msp1!$A:$A,$A33,msp1!$G:$G,$D33) -> 0 | F33: =SUMIFS(n3pp!$F:$F,n3pp!$A:$A,$A33,n3pp!$G:$G,$D33) -> 0 | G33: =SUMIFS('ffp5cs 230V'!$F:$F,'ffp5cs 230V'!$A:$A,$A33,'ffp5cs 230V'!$G:$G,$D33) -> 0 | H33: =SUMIFS('ffp5cs 12V'!$F:$F,'ffp5cs 12V'!$A:$A,$A33,'ffp5cs 12V'!$G:$G,$D33) -> 1 | I33: =SUM(E33:H33) -> 1 | J33: 1 | K33: =IF(I33=0,0,I33+J33) -> 2 | L33: =INDEX(Prix!$E$5:$E$79,MATCH($A33,Prix!$A$5:$A$79,0)) -> 1 | M33: =IF(K33=0,0,ROUNDUP(K33/L33,0)) -> 2 | N33: =IF(INDEX(Prix!$D$5:$D$79,MATCH($A33,Prix!$A$5:$A$79,0))="","",INDEX(Prix!$D$5:$D$79,MATCH($A33,Prix!$A$5:$A$79,0))) | O33: =IF(N33="","",M33*N33) | P33: =INDEX(Prix!$C$5:$C$79,MATCH($A33,Prix!$A$5:$A$79,0)) -> LCSC | Q33: =INDEX(Prix!$H$5:$H$79,MATCH($A33,Prix!$A$5:$A$79,0)) -> Import LCSC | R33: Introuvable au Maroc : LCSC C1666858. Ne pas remplacer par une 15 V. | S33: lien
A34: Z15 | B34: 4. Semi-conducteurs | C34: Diode Zener 15 V 1 W 1N4744A | D34: À acheter | E34: =SUMIFS(msp1!$F:$F,msp1!$A:$A,$A34,msp1!$G:$G,$D34) -> 0 | F34: =SUMIFS(n3pp!$F:$F,n3pp!$A:$A,$A34,n3pp!$G:$G,$D34) -> 0 | G34: =SUMIFS('ffp5cs 230V'!$F:$F,'ffp5cs 230V'!$A:$A,$A34,'ffp5cs 230V'!$G:$G,$D34) -> 0 | H34: =SUMIFS('ffp5cs 12V'!$F:$F,'ffp5cs 12V'!$A:$A,$A34,'ffp5cs 12V'!$G:$G,$D34) -> 1 | I34: =SUM(E34:H34) -> 1 | J34: 1 | K34: =IF(I34=0,0,I34+J34) -> 2 | L34: =INDEX(Prix!$E$5:$E$79,MATCH($A34,Prix!$A$5:$A$79,0)) -> 1 | M34: =IF(K34=0,0,ROUNDUP(K34/L34,0)) -> 2 | N34: =IF(INDEX(Prix!$D$5:$D$79,MATCH($A34,Prix!$A$5:$A$79,0))="","",INDEX(Prix!$D$5:$D$79,MATCH($A34,Prix!$A$5:$A$79,0))) -> 2 | O34: =IF(N34="","",M34*N34) -> 4 | P34: =INDEX(Prix!$C$5:$C$79,MATCH($A34,Prix!$A$5:$A$79,0)) -> MicroPlanet | Q34: =INDEX(Prix!$H$5:$H$79,MATCH($A34,Prix!$A$5:$A$79,0)) -> Maroc | R34: Zener 1 W, variante 15 V (équivalent 1N4744A). | S34: lien
A35: BC337 | B35: 4. Semi-conducteurs | C35: Transistor NPN BC337-40 (TO-92) | D35: À acheter | E35: =SUMIFS(msp1!$F:$F,msp1!$A:$A,$A35,msp1!$G:$G,$D35) -> 1 | F35: =SUMIFS(n3pp!$F:$F,n3pp!$A:$A,$A35,n3pp!$G:$G,$D35) -> 2 | G35: =SUMIFS('ffp5cs 230V'!$F:$F,'ffp5cs 230V'!$A:$A,$A35,'ffp5cs 230V'!$G:$G,$D35) -> 7 | H35: =SUMIFS('ffp5cs 12V'!$F:$F,'ffp5cs 12V'!$A:$A,$A35,'ffp5cs 12V'!$G:$G,$D35) -> 7 | I35: =SUM(E35:H35) -> 17 | J35: 3 | K35: =IF(I35=0,0,I35+J35) -> 20 | L35: =INDEX(Prix!$E$5:$E$79,MATCH($A35,Prix!$A$5:$A$79,0)) -> 1 | M35: =IF(K35=0,0,ROUNDUP(K35/L35,0)) -> 20 | N35: =IF(INDEX(Prix!$D$5:$D$79,MATCH($A35,Prix!$A$5:$A$79,0))="","",INDEX(Prix!$D$5:$D$79,MATCH($A35,Prix!$A$5:$A$79,0))) -> 1 | O35: =IF(N35="","",M35*N35) -> 20 | P35: =INDEX(Prix!$C$5:$C$79,MATCH($A35,Prix!$A$5:$A$79,0)) -> A2itronic | Q35: =INDEX(Prix!$H$5:$H$79,MATCH($A35,Prix!$A$5:$A$79,0)) -> Maroc | R35: Annoncé BC337B/-40 : tout BC337 convient (brochage C-B-E). | S35: lien
A36: IRF4905 | B36: 4. Semi-conducteurs | C36: MOSFET P IRF4905 (TO-220) | D36: À acheter | E36: =SUMIFS(msp1!$F:$F,msp1!$A:$A,$A36,msp1!$G:$G,$D36) -> 2 | F36: =SUMIFS(n3pp!$F:$F,n3pp!$A:$A,$A36,n3pp!$G:$G,$D36) -> 2 | G36: =SUMIFS('ffp5cs 230V'!$F:$F,'ffp5cs 230V'!$A:$A,$A36,'ffp5cs 230V'!$G:$G,$D36) -> 2 | H36: =SUMIFS('ffp5cs 12V'!$F:$F,'ffp5cs 12V'!$A:$A,$A36,'ffp5cs 12V'!$G:$G,$D36) -> 3 | I36: =SUM(E36:H36) -> 9 | J36: 1 | K36: =IF(I36=0,0,I36+J36) -> 10 | L36: =INDEX(Prix!$E$5:$E$79,MATCH($A36,Prix!$A$5:$A$79,0)) -> 1 | M36: =IF(K36=0,0,ROUNDUP(K36/L36,0)) -> 10 | N36: =IF(INDEX(Prix!$D$5:$D$79,MATCH($A36,Prix!$A$5:$A$79,0))="","",INDEX(Prix!$D$5:$D$79,MATCH($A36,Prix!$A$5:$A$79,0))) -> 10 | O36: =IF(N36="","",M36*N36) -> 100 | P36: =INDEX(Prix!$C$5:$C$79,MATCH($A36,Prix!$A$5:$A$79,0)) -> A2itronic | Q36: =INDEX(Prix!$H$5:$H$79,MATCH($A36,Prix!$A$5:$A$79,0)) -> Maroc | R36: Stock non vérifié : appeler avant. Repli LCSC C2564. | S36: lien
A37: LD1117 | B37: 4. Semi-conducteurs | C37: Régulateur LD1117V33 TO-220 (1=GND 2=OUT 3=IN) | D37: À acheter | E37: =SUMIFS(msp1!$F:$F,msp1!$A:$A,$A37,msp1!$G:$G,$D37) -> 1 | F37: =SUMIFS(n3pp!$F:$F,n3pp!$A:$A,$A37,n3pp!$G:$G,$D37) -> 1 | G37: =SUMIFS('ffp5cs 230V'!$F:$F,'ffp5cs 230V'!$A:$A,$A37,'ffp5cs 230V'!$G:$G,$D37) -> 1 | H37: =SUMIFS('ffp5cs 12V'!$F:$F,'ffp5cs 12V'!$A:$A,$A37,'ffp5cs 12V'!$G:$G,$D37) -> 1 | I37: =SUM(E37:H37) -> 4 | J37: 1 | K37: =IF(I37=0,0,I37+J37) -> 5 | L37: =INDEX(Prix!$E$5:$E$79,MATCH($A37,Prix!$A$5:$A$79,0)) -> 1 | M37: =IF(K37=0,0,ROUNDUP(K37/L37,0)) -> 5 | N37: =IF(INDEX(Prix!$D$5:$D$79,MATCH($A37,Prix!$A$5:$A$79,0))="","",INDEX(Prix!$D$5:$D$79,MATCH($A37,Prix!$A$5:$A$79,0))) -> 7.5 | O37: =IF(N37="","",M37*N37) -> 37.5 | P37: =INDEX(Prix!$C$5:$C$79,MATCH($A37,Prix!$A$5:$A$79,0)) -> Megma | Q37: =INDEX(Prix!$H$5:$H$79,MATCH($A37,Prix!$A$5:$A$79,0)) -> Maroc | R37: LM1117T-3.3 TO-220, même brochage que le LD1117V33. Pas de version SOT-223 (CMS). | S37: lien
A38: LED_R | B38: 4. Semi-conducteurs | C38: LED 5 mm rouge | D38: À acheter | E38: =SUMIFS(msp1!$F:$F,msp1!$A:$A,$A38,msp1!$G:$G,$D38) -> 0 | F38: =SUMIFS(n3pp!$F:$F,n3pp!$A:$A,$A38,n3pp!$G:$G,$D38) -> 1 | G38: =SUMIFS('ffp5cs 230V'!$F:$F,'ffp5cs 230V'!$A:$A,$A38,'ffp5cs 230V'!$G:$G,$D38) -> 6 | H38: =SUMIFS('ffp5cs 12V'!$F:$F,'ffp5cs 12V'!$A:$A,$A38,'ffp5cs 12V'!$G:$G,$D38) -> 6 | I38: =SUM(E38:H38) -> 13 | J38: 2 | K38: =IF(I38=0,0,I38+J38) -> 15 | L38: =INDEX(Prix!$E$5:$E$79,MATCH($A38,Prix!$A$5:$A$79,0)) -> 1 | M38: =IF(K38=0,0,ROUNDUP(K38/L38,0)) -> 15 | N38: =IF(INDEX(Prix!$D$5:$D$79,MATCH($A38,Prix!$A$5:$A$79,0))="","",INDEX(Prix!$D$5:$D$79,MATCH($A38,Prix!$A$5:$A$79,0))) -> 1 | O38: =IF(N38="","",M38*N38) -> 15 | P38: =INDEX(Prix!$C$5:$C$79,MATCH($A38,Prix!$A$5:$A$79,0)) -> Moussasoft | Q38: =INDEX(Prix!$H$5:$H$79,MATCH($A38,Prix!$A$5:$A$79,0)) -> Maroc | S38: lien
A39: LED_V | B39: 4. Semi-conducteurs | C39: LED 5 mm verte | D39: À acheter | E39: =SUMIFS(msp1!$F:$F,msp1!$A:$A,$A39,msp1!$G:$G,$D39) -> 0 | F39: =SUMIFS(n3pp!$F:$F,n3pp!$A:$A,$A39,n3pp!$G:$G,$D39) -> 0 | G39: =SUMIFS('ffp5cs 230V'!$F:$F,'ffp5cs 230V'!$A:$A,$A39,'ffp5cs 230V'!$G:$G,$D39) -> 1 | H39: =SUMIFS('ffp5cs 12V'!$F:$F,'ffp5cs 12V'!$A:$A,$A39,'ffp5cs 12V'!$G:$G,$D39) -> 1 | I39: =SUM(E39:H39) -> 2 | J39: 1 | K39: =IF(I39=0,0,I39+J39) -> 3 | L39: =INDEX(Prix!$E$5:$E$79,MATCH($A39,Prix!$A$5:$A$79,0)) -> 1 | M39: =IF(K39=0,0,ROUNDUP(K39/L39,0)) -> 3 | N39: =IF(INDEX(Prix!$D$5:$D$79,MATCH($A39,Prix!$A$5:$A$79,0))="","",INDEX(Prix!$D$5:$D$79,MATCH($A39,Prix!$A$5:$A$79,0))) -> 0.9 | O39: =IF(N39="","",M39*N39) -> 2.7 | P39: =INDEX(Prix!$C$5:$C$79,MATCH($A39,Prix!$A$5:$A$79,0)) -> Shop4Makers | Q39: =INDEX(Prix!$H$5:$H$79,MATCH($A39,Prix!$A$5:$A$79,0)) -> Maroc | S39: lien
A40: SRD05 | B40: 5. Relais et protection secteur | C40: Relais Songle SRD-05VDC-SL-C (composant seul, pas le module) | D40: À acheter | E40: =SUMIFS(msp1!$F:$F,msp1!$A:$A,$A40,msp1!$G:$G,$D40) -> 0 | F40: =SUMIFS(n3pp!$F:$F,n3pp!$A:$A,$A40,n3pp!$G:$G,$D40) -> 1 | G40: =SUMIFS('ffp5cs 230V'!$F:$F,'ffp5cs 230V'!$A:$A,$A40,'ffp5cs 230V'!$G:$G,$D40) -> 6 | H40: =SUMIFS('ffp5cs 12V'!$F:$F,'ffp5cs 12V'!$A:$A,$A40,'ffp5cs 12V'!$G:$G,$D40) -> 6 | I40: =SUM(E40:H40) -> 13 | J40: 1 | K40: =IF(I40=0,0,I40+J40) -> 14 | L40: =INDEX(Prix!$E$5:$E$79,MATCH($A40,Prix!$A$5:$A$79,0)) -> 1 | M40: =IF(K40=0,0,ROUNDUP(K40/L40,0)) -> 14 | N40: =IF(INDEX(Prix!$D$5:$D$79,MATCH($A40,Prix!$A$5:$A$79,0))="","",INDEX(Prix!$D$5:$D$79,MATCH($A40,Prix!$A$5:$A$79,0))) -> 18 | O40: =IF(N40="","",M40*N40) -> 252 | P40: =INDEX(Prix!$C$5:$C$79,MATCH($A40,Prix!$A$5:$A$79,0)) -> Moussasoft | Q40: =INDEX(Prix!$H$5:$H$79,MATCH($A40,Prix!$A$5:$A$79,0)) -> Maroc | R40: Composant seul 5 broches, pas un module relais. 324 en stock. | S40: lien
A41: VARISTANCE | B41: 5. Relais et protection secteur | C41: Varistance 14D471K (ou 10D471K), pas 7,5 mm | D41: À acheter | E41: =SUMIFS(msp1!$F:$F,msp1!$A:$A,$A41,msp1!$G:$G,$D41) -> 0 | F41: =SUMIFS(n3pp!$F:$F,n3pp!$A:$A,$A41,n3pp!$G:$G,$D41) -> 0 | G41: =SUMIFS('ffp5cs 230V'!$F:$F,'ffp5cs 230V'!$A:$A,$A41,'ffp5cs 230V'!$G:$G,$D41) -> 1 | H41: =SUMIFS('ffp5cs 12V'!$F:$F,'ffp5cs 12V'!$A:$A,$A41,'ffp5cs 12V'!$G:$G,$D41) -> 0 | I41: =SUM(E41:H41) -> 1 | J41: 1 | K41: =IF(I41=0,0,I41+J41) -> 2 | L41: =INDEX(Prix!$E$5:$E$79,MATCH($A41,Prix!$A$5:$A$79,0)) -> 1 | M41: =IF(K41=0,0,ROUNDUP(K41/L41,0)) -> 2 | N41: =IF(INDEX(Prix!$D$5:$D$79,MATCH($A41,Prix!$A$5:$A$79,0))="","",INDEX(Prix!$D$5:$D$79,MATCH($A41,Prix!$A$5:$A$79,0))) -> 4 | O41: =IF(N41="","",M41*N41) -> 8 | P41: =INDEX(Prix!$C$5:$C$79,MATCH($A41,Prix!$A$5:$A$79,0)) -> MicroPlanet | Q41: =INDEX(Prix!$H$5:$H$79,MATCH($A41,Prix!$A$5:$A$79,0)) -> Maroc | R41: Variante 470 V (471). | S41: lien
A42: PORTEFUS_5x20 | B42: 5. Relais et protection secteur | C42: Porte-fusible 5×20 pour circuit imprimé, à capot (pas 22–22,6 mm) | D42: À acheter | E42: =SUMIFS(msp1!$F:$F,msp1!$A:$A,$A42,msp1!$G:$G,$D42) -> 0 | F42: =SUMIFS(n3pp!$F:$F,n3pp!$A:$A,$A42,n3pp!$G:$G,$D42) -> 0 | G42: =SUMIFS('ffp5cs 230V'!$F:$F,'ffp5cs 230V'!$A:$A,$A42,'ffp5cs 230V'!$G:$G,$D42) -> 1 | H42: =SUMIFS('ffp5cs 12V'!$F:$F,'ffp5cs 12V'!$A:$A,$A42,'ffp5cs 12V'!$G:$G,$D42) -> 0 | I42: =SUM(E42:H42) -> 1 | J42: 0 | K42: =IF(I42=0,0,I42+J42) -> 1 | L42: =INDEX(Prix!$E$5:$E$79,MATCH($A42,Prix!$A$5:$A$79,0)) -> 1 | M42: =IF(K42=0,0,ROUNDUP(K42/L42,0)) -> 1 | N42: =IF(INDEX(Prix!$D$5:$D$79,MATCH($A42,Prix!$A$5:$A$79,0))="","",INDEX(Prix!$D$5:$D$79,MATCH($A42,Prix!$A$5:$A$79,0))) -> 4 | O42: =IF(N42="","",M42*N42) -> 4 | P42: =INDEX(Prix!$C$5:$C$79,MATCH($A42,Prix!$A$5:$A$79,0)) -> Moussasoft | Q42: =INDEX(Prix!$H$5:$H$79,MATCH($A42,Prix!$A$5:$A$79,0)) -> Maroc | R42: Mesurer l'entraxe des pattes AVANT achat : 22,0–22,6 mm. Sinon LCSC C3131. | S42: lien
A43: FUS_T1A | B43: 5. Relais et protection secteur | C43: Fusible verre 5×20 temporisé T1A | D43: À acheter | E43: =SUMIFS(msp1!$F:$F,msp1!$A:$A,$A43,msp1!$G:$G,$D43) -> 0 | F43: =SUMIFS(n3pp!$F:$F,n3pp!$A:$A,$A43,n3pp!$G:$G,$D43) -> 0 | G43: =SUMIFS('ffp5cs 230V'!$F:$F,'ffp5cs 230V'!$A:$A,$A43,'ffp5cs 230V'!$G:$G,$D43) -> 3 | H43: =SUMIFS('ffp5cs 12V'!$F:$F,'ffp5cs 12V'!$A:$A,$A43,'ffp5cs 12V'!$G:$G,$D43) -> 0 | I43: =SUM(E43:H43) -> 3 | J43: 0 | K43: =IF(I43=0,0,I43+J43) -> 3 | L43: =INDEX(Prix!$E$5:$E$79,MATCH($A43,Prix!$A$5:$A$79,0)) -> 1 | M43: =IF(K43=0,0,ROUNDUP(K43/L43,0)) -> 3 | N43: =IF(INDEX(Prix!$D$5:$D$79,MATCH($A43,Prix!$A$5:$A$79,0))="","",INDEX(Prix!$D$5:$D$79,MATCH($A43,Prix!$A$5:$A$79,0))) -> 0.5 | O43: =IF(N43="","",M43*N43) -> 1.5 | P43: =INDEX(Prix!$C$5:$C$79,MATCH($A43,Prix!$A$5:$A$79,0)) -> Megma | Q43: =INDEX(Prix!$H$5:$H$79,MATCH($A43,Prix!$A$5:$A$79,0)) -> Maroc | R43: Le type T (temporisé) n'est pas indiqué : demander « T1A » ; un fusible rapide F peut sauter au branchement. | S43: lien
A44: HLK20M05 | B44: 5. Relais et protection secteur | C44: Module Hi-Link HLK-20M05 (230 V → 5 V 3,6 A) | D44: À acheter | E44: =SUMIFS(msp1!$F:$F,msp1!$A:$A,$A44,msp1!$G:$G,$D44) -> 0 | F44: =SUMIFS(n3pp!$F:$F,n3pp!$A:$A,$A44,n3pp!$G:$G,$D44) -> 0 | G44: =SUMIFS('ffp5cs 230V'!$F:$F,'ffp5cs 230V'!$A:$A,$A44,'ffp5cs 230V'!$G:$G,$D44) -> 1 | H44: =SUMIFS('ffp5cs 12V'!$F:$F,'ffp5cs 12V'!$A:$A,$A44,'ffp5cs 12V'!$G:$G,$D44) -> 0 | I44: =SUM(E44:H44) -> 1 | J44: 0 | K44: =IF(I44=0,0,I44+J44) -> 1 | L44: =INDEX(Prix!$E$5:$E$79,MATCH($A44,Prix!$A$5:$A$79,0)) -> 1 | M44: =IF(K44=0,0,ROUNDUP(K44/L44,0)) -> 1 | N44: =IF(INDEX(Prix!$D$5:$D$79,MATCH($A44,Prix!$A$5:$A$79,0))="","",INDEX(Prix!$D$5:$D$79,MATCH($A44,Prix!$A$5:$A$79,0))) -> 90 | O44: =IF(N44="","",M44*N44) -> 90 | P44: =INDEX(Prix!$C$5:$C$79,MATCH($A44,Prix!$A$5:$A$79,0)) -> Shop4Makers | Q44: =INDEX(Prix!$H$5:$H$79,MATCH($A44,Prix!$A$5:$A$79,0)) -> Maroc | R44: Authenticité non garantie : mesurer les entraxes des broches (COMMANDE.md §0.3) avant de souder. | S44: lien
A45: BORNIER_2P | B45: 6. Connectique carte | C45: Bornier à vis 2 pôles pas 5,08 (KF301-2P) | D45: À acheter | E45: =SUMIFS(msp1!$F:$F,msp1!$A:$A,$A45,msp1!$G:$G,$D45) -> 5 | F45: =SUMIFS(n3pp!$F:$F,n3pp!$A:$A,$A45,n3pp!$G:$G,$D45) -> 5 | G45: =SUMIFS('ffp5cs 230V'!$F:$F,'ffp5cs 230V'!$A:$A,$A45,'ffp5cs 230V'!$G:$G,$D45) -> 5 | H45: =SUMIFS('ffp5cs 12V'!$F:$F,'ffp5cs 12V'!$A:$A,$A45,'ffp5cs 12V'!$G:$G,$D45) -> 8 | I45: =SUM(E45:H45) -> 23 | J45: 3 | K45: =IF(I45=0,0,I45+J45) -> 26 | L45: =INDEX(Prix!$E$5:$E$79,MATCH($A45,Prix!$A$5:$A$79,0)) -> 1 | M45: =IF(K45=0,0,ROUNDUP(K45/L45,0)) -> 26 | N45: =IF(INDEX(Prix!$D$5:$D$79,MATCH($A45,Prix!$A$5:$A$79,0))="","",INDEX(Prix!$D$5:$D$79,MATCH($A45,Prix!$A$5:$A$79,0))) -> 2 | O45: =IF(N45="","",M45*N45) -> 52 | P45: =INDEX(Prix!$C$5:$C$79,MATCH($A45,Prix!$A$5:$A$79,0)) -> MicroPlanet | Q45: =INDEX(Prix!$H$5:$H$79,MATCH($A45,Prix!$A$5:$A$79,0)) -> Maroc | R45: KF301 annoncé au pas de 5,0 mm : se monte sur les trous 5,08 (écart 0,08 mm). | S45: lien
...

Sheet Prix
A1: Catalogue des prix — fournisseurs marocains
A2: Relevé le 18/10/2026 sur les pages produits, prix en DH tels qu'affichés (TTC). Cellules bleues = à mettre à jour ; toutes les autres feuilles se recalculent depuis celle-ci.
A4: ID | B4: Article | C4: Fournisseur | D4: Prix du lot (DH) | E4: Taille du lot | F4: Unité de vente | G4: Prix unitaire (DH) | H4: Source | I4: Lien | J4: Remarque achat | K4: Relevé le
A5: PCB | B5: Circuit imprimé n3-universal rev 0.2.2 (JLCPCB, 2 oz) | C5: JLCPCB | E5: 1 | F5: carte | G5: =IF(D5="","",D5/E5) | H5: Import | I5: lien | J5: Commande unique de 10 cartes : ≈ 55–85 $ les 5 + port (COMMANDE.md) ; prix réel au devis JLCPCB. | K5: 18/10/2026
A6: ESP32_DEVKIT | B6: ESP32 DevKit V1 30 broches (WROOM-32) | C6: Shop4Makers | D6: 113 | E6: 1 | F6: pièce | G6: =IF(D6="","",D6/E6) -> 113 | H6: Maroc | I6: lien | J6: ESP32 WROOM CP2102 30 broches. Ne pas importer (ANRT). Repli A2itronic 120 DH. | K6: 18/10/2026
A7: R_220 | B7: Résistance 220 Ω 1/4 W | C7: MicroPlanet | D7: 1.5 | E7: 5 | F7: lot de 5 | G7: =IF(D7="","",D7/E7) -> 0.3 | H7: Maroc | I7: lien | J7: 1/4 W 1 %, vendues par 5. | K7: 18/10/2026
A8: R_1k | B8: Résistance 1 kΩ 1/4 W | C8: MicroPlanet | D8: 1.5 | E8: 5 | F8: lot de 5 | G8: =IF(D8="","",D8/E8) -> 0.3 | H8: Maroc | I8: lien | J8: 1/4 W 1 %, vendues par 5. | K8: 18/10/2026
A9: R_2k | B9: Résistance 2 kΩ 1/4 W (2,2 kΩ convient) | C9: MicroPlanet | D9: 1.5 | E9: 5 | F9: lot de 5 | G9: =IF(D9="","",D9/E9) -> 0.3 | H9: Maroc | I9: lien | J9: 1/4 W 1 %, vendues par 5. | K9: 18/10/2026
A10: R_4.7k | B10: Résistance 4,7 kΩ 1/4 W | C10: MicroPlanet | D10: 1.5 | E10: 5 | F10: lot de 5 | G10: =IF(D10="","",D10/E10) -> 0.3 | H10: Maroc | I10: lien | J10: 1/4 W 1 %, vendues par 5. | K10: 18/10/2026
A11: R_10k | B11: Résistance 10 kΩ 1/4 W | C11: MicroPlanet | D11: 1.5 | E11: 5 | F11: lot de 5 | G11: =IF(D11="","",D11/E11) -> 0.3 | H11: Maroc | I11: lien | J11: 1/4 W 1 %, vendues par 5. | K11: 18/10/2026
A12: R_18k | B12: Résistance 18 kΩ 1/4 W | C12: MicroPlanet | D12: 1.5 | E12: 5 | F12: lot de 5 | G12: =IF(D12="","",D12/E12) -> 0.3 | H12: Maroc | I12: lien | J12: 1/4 W 1 %, vendues par 5. | K12: 18/10/2026
A13: R_100k | B13: Résistance 100 kΩ 1/4 W | C13: MicroPlanet | D13: 1.5 | E13: 5 | F13: lot de 5 | G13: =IF(D13="","",D13/E13) -> 0.3 | H13: Maroc | I13: lien | J13: 1/4 W 1 %, vendues par 5. | K13: 18/10/2026
A14: C_100n | B14: Condensateur céramique 100 nF (pas 5 mm) | C14: A2itronic | D14: 0.5 | E14: 1 | F14: pièce | G14: =IF(D14="","",D14/E14) -> 0.5 | H14: Maroc | I14: lien | J14: Céramique 50 V. | K14: 18/10/2026
A15: C_10u25 | B15: Condensateur électrolytique 10 µF 25 V | C15: A2itronic | D15: 1 | E15: 1 | F15: pièce | G15: =IF(D15="","",D15/E15) -> 1 | H15: Maroc | I15: lien | J15: Proposé en 50 V (mieux que 25 V). | K15: 18/10/2026
A16: C_100u16 | B16: Condensateur électrolytique 100 µF 16 V | C16: A2itronic | D16: 1 | E16: 1 | F16: pièce | G16: =IF(D16="","",D16/E16) -> 1 | H16: Maroc | I16: lien | J16: 5×7 mm. | K16: 18/10/2026
A17: C_470u16 | B17: Condensateur électrolytique 470 µF 16 V (25 V convient) | C17: A2itronic | D17: 2 | E17: 1 | F17: pièce | G17: =IF(D17="","",D17/E17) -> 2 | H17: Maroc | I17: lien | J17: Proposé en 25 V, 8×12 mm (empreinte 8 mm) : convient. | K17: 18/10/2026
... A19: C_1000u16 | B19: Condensateur électrolytique 1000 µF 16 V (diam. 10 mm) | C19: A2itronic | D19: 3 | E19: 1 | F19: pièce | G19: =IF(D19="","",D19/E19) -> 3 | H19: Maroc | I19: lien | J19: Page ambiguë 16/25 V : les deux conviennent, mais diamètre ≤ 10 mm et pas 5 mm. | K19: 18/10/2026
A20: 1N4007 | B20: Diode 1N4007 (roue libre des bobines de relais) | C20: Shop4Makers | D20: 0.9 | E20: 1 | F20: pièce | G20: =IF(D20="","",D20/E20) -> 0.9 | H20: Maroc | I20: lien | K20: 18/10/2026
A21: BAT85 | B21: Diode Schottky BAT85 / BAT43 / BAT42 (DO-35) | C21: Moussasoft | D21: 2 | E21: 1 | F21: pièce | G21: =IF(D21="","",D21/E21) -> 2 | H21: Maroc | I21: lien | J21: Boîtier DO-34, se pose sur les trous DO-35. BAT43/42/54 introuvables au Maroc. | K21: 18/10/2026
A22: TVS_6V8 | B22: Diode TVS 1.5KE6.8A (ou P6KE6.8A) | C22: LCSC | E22: 1 | F22: pièce | G22: =IF(D22="","",D22/E22) | H22: Import LCSC | I22: lien | J22: Introuvable au Maroc : LCSC C412500 (repli P6KE6.8A C409413), colis combiné JLCPCB. | K22: 18/10/2026
A23: TVS_18 | B23: Diode TVS 1.5KE18A (ou P6KE18A) — PAS 15 V | C23: LCSC | E23: 1 | F23: pièce | G23: =IF(D23="","",D23/E23) | H23: Import LCSC | I23: lien | J23: Introuvable au Maroc : LCSC C1666858. Ne pas remplacer par une 15 V. | K23: 18/10/2026
A24: Z15 | B24: Diode Zener 15 V 1 W 1N4744A | C24: MicroPlanet | D24: 2 | E24: 1 | F24: pièce | G24: =IF(D24="","",D24/E24) -> 2 | H24: Maroc | I24: lien | J24: Zener 1 W, variante 15 V (équivalent 1N4744A). | K24: 18/10/2026
A25: BC337 | B25: Transistor NPN BC337-40 (TO-92) | C25: A2itronic | D25: 1 | E25: 1 | F25: pièce | G25: =IF(D25="","",D25/E25) -> 1 | H25: Maroc | I25: lien | J25: Annoncé BC337B/-40 : tout BC337 convient (brochage C-B-E). | K25: 18/10/2026
A26: IRF4905 | B26: MOSFET P IRF4905 (TO-220) | C26: A2itronic | D26: 10 | E26: 1 | F26: pièce | G26: =IF(D26="","",D26/E26) -> 10 | H26: Maroc | I26: lien | J26: Stock non vérifié : appeler avant. Repli LCSC C2564. | K26: 18/10/2026
A27: LD1117 | B27: Régulateur LD1117V33 TO-220 (1=GND 2=OUT 3=IN) | C27: Megma | D27: 7.5 | E27: 1 | F27: pièce | G27: =IF(D27="","",D27/E27) -> 7.5 | H27: Maroc | I27: lien | J27: LM1117T-3.3 TO-220, même brochage que le LD1117V33. Pas de version SOT-223 (CMS). | K27: 18/10/2026
A28: LED_R | B28: LED 5 mm rouge | C28: Moussasoft | D28: 1 | E28: 1 | F28: pièce | G28: =IF(D28="","",D28/E28) -> 1 | H28: Maroc | I28: lien | K28: 18/10/2026
A29: LED_V | B29: LED 5 mm verte | C29: Shop4Makers | D29: 0.9 | E29: 1 | F29: pièce | G29: =IF(D29="","",D29/E29) -> 0.9 | H29: Maroc | I29: lien | K29: 18/10/2026
A30: SRD05 | B30: Relais Songle SRD-05VDC-SL-C (composant seul, pas le module) | C30: Moussasoft | D30: 18 | E30: 1 | F30: pièce | G30: =IF(D30="","",D30/E30) -> 18 | H30: Maroc | I30: lien | J30: Composant seul 5 broches, pas un module relais. 324 en stock. | K30: 18/10/2026
A31: VARISTANCE | B31: Varistance 14D471K (ou 10D471K), pas 7,5 mm | C31: MicroPlanet | D31: 4 | E31: 1 | F31: pièce | G31: =IF(D31="","",D31/E31) -> 4 | H31: Maroc | I31: lien | J31: Variante 470 V (471). | K31: 18/10/2026
A32: PORTEFUS_5x20 | B32: Porte-fusible 5×20 pour circuit imprimé, à capot (pas 22–22,6 mm) | C32: Moussasoft | D32: 4 | E32: 1 | F32: pièce | G32: =IF(D32="","",D32/E32) -> 4 | H32: Maroc | I32: lien | J32: Mesurer l'entraxe des pattes AVANT achat : 22,0–22,6 mm. Sinon LCSC C3131. | K32: 18/10/2026
A33: FUS_T1A | B33: Fusible verre 5×20 temporisé T1A | C33: Megma | D33: 0.5 | E33: 1 | F33: pièce | G33: =IF(D33="","",D33/E33) -> 0.5 | H33: Maroc | I33: lien | J33: Le type T (temporisé) n'est pas indiqué : demander « T1A » ; un fusible rapide F peut sauter au branchement. | K33: 18/10/2026
A34: HLK20M05 | B34: Module Hi-Link HLK-20M05 (230 V → 5 V 3,6 A) | C34: Shop4Makers | D34: 90 | E34: 1 | F34: pièce | G34: =IF(D34="","",D34/E34) -> 90 | H34: Maroc | I34: lien | J34: Authenticité non garantie : mesurer les entraxes des broches (COMMANDE.md §0.3) avant de souder. | K34: 18/10/2026
A35: BORNIER_2P | B35: Bornier à vis 2 pôles pas 5,08 (KF301-2P) | C35: MicroPlanet | D35: 2 | E35: 1 | F35: pièce | G35: =IF(D35="","",D35/E35) -> 2 | H35: Maroc | I35: lien | J35: KF301 annoncé au pas de 5,0 mm : se monte sur les trous 5,08 (écart 0,08 mm). | K35: 18/10/2026
A36: BORNIER_3P | B36: Bornier à vis 3 pôles pas 5,08 (KF301-3P) | C36: MicroPlanet | D36: 3 | E36: 1 | F36: pièce | G36: =IF(D36="","",D36/E36) -> 3 | H36: Maroc | I36: lien | J36: KF301 pas 5,0 mm : se monte sur les trous 5,08. | K36: 18/10/2026
A37: BORNIER_4P | B37: Bornier à vis 4 pôles pas 5,08 (ou 2+2 emboîtés) | C37: MicroPlanet | D37: 5 | E37: 1 | F37: pièce | G37: =IF(D37="","",D37/E37) -> 5 | H37: Maroc | I37: lien | J37: KF128-4P. Sur 4 pôles, l'écart 5,0/5,08 cumule 0,24 mm : présenter avant de souder, ou 2 × KF301-2P emboîtés. | K37: 18/10/2026
A38: BARRETTE_F | B38: Barrette femelle sécable 1×40 pas 2,54 | C38: Moussasoft | D38: 5 | E38: 1 | F38: barrette 1×40 | G38: =IF(D38="","",D38/E38) -> 5 | H38: Maroc | I38: lien | J38: Une broche perdue à chaque coupe (compté). | K38: 18/10/2026
A39: BARRETTE_M | B39: Barrette mâle sécable 1×40 pas 2,54 | C39: Moussasoft | D39: 4 | E39: 1 | F39: barrette 1×40 | G39: =IF(D39="","",D39/E39) -> 4 | H39: Maroc | I39: lien | K39: 18/10/2026
A40: CAVALIER | B40: Cavalier (jumper) 2,54 mm | C40: Shop4Makers | D40: 5 | E40: 10 | F40: lot de 10 | G40: =IF(D40="","",D40/E40) -> 0.5 | H40: Maroc | I40: lien | J40: Prix du plus petit lot (bas de la fourchette affichée). | K40: 18/10/2026
A41: JACK_DC | B41: Jack DC femelle 5,5×2,1 pour circuit imprimé (DC-005) | C41: ShoppingMaroc | D41: 4 | E41: 1 | F41: pièce | G41: =IF(D41="","",D41/E41) -> 4 | H41: Maroc | I41: lien | J41: DC-005 traversant 3 broches. | K41: 18/10/2026
A42: FIL | B42: Pont de fil à la place de D5 (chute de patte de résistance) | C42: — | D42: 0 | E42: 1 | F42: — | G42: =IF(D42="","",D42/E42) -> 0 | H42: Maroc | J42: Chute de patte de résistance : gratuit. | K42: 18/10/2026
...

Sheet msp1
A1: msp1 — station météo + tracker (18650 + solaire)
A2: Carte n3-universal rev 0.2.2 — composants à poser et à acheter pour UNE unité. Prix du 18/10/2026 (feuille Prix). Les quantités (bleu) sont modifiables ; l'achat groupé arrondi aux lots est dans « Global ».
A4: Consignes de pose de ce profil
B5: • Chaîne d'alimentation : panneau 6 V → TP4056 → 18650 → boost réglé à 5,1 V → J1 (bornier).
B6: • JP1 ôté (parqué en 2-3) : capteurs, OLED et servos coupés pendant le sommeil.
B7: • JP12 en 2-3 (pont 1S 100k/100k) ; JP16-JP19 FERMÉS (LDR tracker) ; JP21 FERMÉ (DHT extérieur) ; JP13-JP15 et JP20 OUVERTS.
B8: • NE PAS poser : LED5/R13, R17-R19, R27, tout l'étage relais (K1-K6…), Hi-Link, section 12 V.
B9: • Firmware : seuil de veille d'urgence à régler pour ≥ 3,3 V cellule. Cellule à l'ombre.
C11: Total à acheter, une unité (DH) | J11: =SUMIFS(J18:J60,G18:G60,"À acheter") -> 1072.1
C12: Options (DH) | J12: =SUMIFS(J18:J60,G18:G60,"Option") -> 170
C13: Déjà possédé — valeur indicative (DH) | J13: =SUMIFS(J18:J60,G18:G60,"Déjà possédé") -> 15
C14: Articles à acheter sans prix en ligne (import LCSC, quincaillerie, PCB) | J14: =SUMPRODUCT((G18:G60="À acheter")*(I18:I60="")) -> 3
A17: ID | B17: Catégorie | C17: Article | D17: Réf. carte | E17: Rôle | F17: Qté | G17: Statut | H17: Fournisseur | I17: Prix unitaire (DH) | J17: Coût (DH) | K17: Remarques | L17: Lien
A18: PCB | B18: 1. Carte et cerveau | C18: Circuit imprimé n3-universal rev 0.2.2 (JLCPCB, 2 oz) | D18: — | E18: Circuit imprimé n3-universal rev 0.2.2 | F18: 1 | G18: À acheter | H18: =INDEX(Prix!$C$5:$C$79,MATCH($A18,Prix!$A$5:$A$79,0)) -> JLCPCB | I18: =IFERROR(INDEX(Prix!$G$5:$G$79,MATCH($A18,Prix!$A$5:$A$79,0)),"") | J18: =IF(I18="","",F18*I18) | L18: lien
A19: ESP32_DEVKIT | B19: 1. Carte et cerveau | C19: ESP32 DevKit V1 30 broches (WROOM-32) | D19: A1 | E19: Module ESP32-WROOM-32 DevKit V1 30 broches, sur 2 supports 1x15 | F19: 1 | G19: À acheter | H19: =INDEX(Prix!$C$5:$C$79,MATCH($A19,Prix!$A$5:$A$79,0)) -> Shop4Makers | I19: =IFERROR(INDEX(Prix!$G$5:$G$79,MATCH($A19,Prix!$A$5:$A$79,0)),"") -> 113 | J19: =IF(I19="","",F19*I19) -> 113 | K19: Enfiché sur ses supports, jamais soudé. Vérifier l'écart des rangées (25,4 ou 27,94 mm : support droit sur A ou A'). | L19: lien
A20: R_220 | B20: 2. Résistances | C20: Résistance 220 Ω 1/4 W | D20: R20, R21 | E20: Série signal servo gros; Série signal servo petits | F20: 2 | G20: À acheter | H20: =INDEX(Prix!$C$5:$C$79,MATCH($A20,Prix!$A$5:$A$79,0)) -> MicroPlanet | I20: =IFERROR(INDEX(Prix!$G$5:$G$79,MATCH($A20,Prix!$A$5:$A$79,0)),"") -> 0.3 | J20: =IF(I20="","",F20*I20) -> 0.6 | L20: lien
A21: R_1k | B21: 2. Résistances | C21: Résistance 1 kΩ 1/4 W | D21: R34, R49, R50, R51, R52, R53, R54 | E21: Base commande gate; Série ADC_VBAT; Série ADC_A; Série ADC_B ; … | F21: 7 | G21: À acheter | H21: =INDEX(Prix!$C$5:$C$79,MATCH($A21,Prix!$A$5:$A$79,0)) -> MicroPlanet | I21: =IFERROR(INDEX(Prix!$G$5:$G$79,MATCH($A21,Prix!$A$5:$A$79,0)),"") -> 0.3 | J21: =IF(I21="","",F21*I21) -> 2.1 | L21: lien
A22: R_4.7k | B22: 2. Résistances | C22: Résistance 4,7 kΩ 1/4 W | D22: R24, R25, R26 | E22: Pull-up bus 1-Wire DS18B20; Pull-up I2C SDA; Pull-up I2C SCL | F22: 3 | G22: À acheter | H22: =INDEX(Prix!$C$5:$C$79,MATCH($A22,Prix!$A$5:$A$79,0)) -> MicroPlanet | I22: =IFERROR(INDEX(Prix!$G$5:$G$79,MATCH($A22,Prix!$A$5:$A$79,0)),"") -> 0.3 | J22: =IF(I22="","",F22*I22) -> 0.9 | L22: lien
A23: R_10k | B23: 2. Résistances | C23: Résistance 10 kΩ 1/4 W | D23: R23, R43, R44, R45, R46, R47, R48 | E23: Pull-up data DHT11; Bas de pont ADC_A (en circuit si JP16 FERMÉ : LDR msp; Bas de pont ADC_B (en circuit si JP17 FERMÉ : LDR msp; Bas de pont ADC_C (en circuit si JP18 FERMÉ : LDR msp ; … | F23: 7 | G23: À acheter | H23: =INDEX(Prix!$C$5:$C$79,MATCH($A23,Prix!$A$5:$A$79,0)) -> MicroPlanet | I23: =IFERROR(INDEX(Prix!$G$5:$G$79,MATCH($A23,Prix!$A$5:$A$79,0)),"") -> 0.3 | J23: =IF(I23="","",F23*I23) -> 2.1 | L23: lien
A24: R_18k | B24: 2. Résistances | C24: Résistance 18 kΩ 1/4 W | D24: R39 | E24: Bas du pont VBAT profil bus 12V : 100k/18k | F24: 1 | G24: À acheter | H24: =INDEX(Prix!$C$5:$C$79,MATCH($A24,Prix!$A$5:$A$79,0)) -> MicroPlanet | I24: =IFERROR(INDEX(Prix!$G$5:$G$79,MATCH($A24,Prix!$A$5:$A$79,0)),"") -> 0.3 | J24: =IF(I24="","",F24*I24) -> 0.3 | L24: lien
A25: R_100k | B25: 2. Résistances | C25: Résistance 100 kΩ 1/4 W | D25: R35, R38, R57, R58 | E25: Pull-up grille P-MOSFET vers +5V; Haut du pont VBAT; Grille de Q12 vers GND; Bas du pont VBAT profil 1S : 100k/100k | F25: 4 | G25: À acheter | H25: =INDEX(Prix!$C$5:$C$79,MATCH($A25,Prix!$A$5:$A$79,0)) -> MicroPlanet | I25: =IFERROR(INDEX(Prix!$G$5:$G$79,MATCH($A25,Prix!$A$5:$A$79,0)),"") -> 0.3 | J25: =IF(I25="","",F25*I25) -> 1.2 | L25: lien
A26: C_100n | B26: 3. Condensateurs | C26: Condensateur céramique 100 nF (pas 5 mm) | D26: C3, C4, C6, C7, C8, C9, C10, C13 | E26: Découplage 3V3 capteurs; Découplage 3V3 I2C; Filtre ADC ADC_A; Filtre ADC ADC_B ; … | F26: 8 | G26: À acheter | H26: =INDEX(Prix!$C$5:$C$79,MATCH($A26,Prix!$A$5:$A$79,0)) -> A2itronic | I26: =IFERROR(INDEX(Prix!$G$5:$G$79,MATCH($A26,Prix!$A$5:$A$79,0)),"") -> 0.5 | J26: =IF(I26="","",F26*I26) -> 4 | L26: lien
A27: C_10u25 | B27: 3. Condensateurs | C27: Condensateur électrolytique 10 µF 25 V | D27: C11 | E27: Entrée LDO | F27: 1 | G27: À acheter | H27: =INDEX(Prix!$C$5:$C$79,MATCH($A27,Prix!$A$5:$A$79,0)) -> A2itronic | I27: =IFERROR(INDEX(Prix!$G$5:$G$79,MATCH($A27,Prix!$A$5:$A$79,0)),"") -> 1 | J27: =IF(I27="","",F27*I27) -> 1 | L27: lien
A28: C_100u16 | B28: 3. Condensateurs | C28: Condensateur électrolytique 100 µF 16 V | D28: C12 | E28: Sortie LDO | F28: 1 | G28: À acheter | H28: =INDEX(Prix!$C$5:$C$79,MATCH($A28,Prix!$A$5:$A$79,0)) -> A2itronic | I28: =IFERROR(INDEX(Prix!$G$5:$G$79,MATCH($A28,Prix!$A$5:$A$79,0)),"") -> 1 | J28: =IF(I28="","",F28*I28) -> 1 | L28: lien
A29: C_470u16 | B29: 3. Condensateurs | C29: Condensateur électrolytique 470 µF 16 V (25 V convient) | D29: C2 | E29: Réservoir du rail 5 V commuté LDO_IN côté servos | F29: 1 | G29: À acheter | H29: =INDEX(Prix!$C$5:$C$79,MATCH($A29,Prix!$A$5:$A$79,0)) -> A2itronic | I29: =IFERROR(INDEX(Prix!$G$5:$G$79,MATCH($A29,Prix!$A$5:$A$79,0)),"") -> 2 | J29: =IF(I29="","",F29*I29) -> 2 | L29: lien
A30: C_1000u16 | B30: 3. Condensateurs | C30: Condensateur électrolytique 1000 µF 16 V (diam. 10 mm) | D30: C1 | E30: Réservoir rail 5V | F30: 1 | G30: À acheter | H30: =INDEX(Prix!$C$5:$C$79,MATCH($A30,Prix!$A$5:$A$79,0)) -> A2itronic | I30: =IFERROR(INDEX(Prix!$G$5:$G$79,MATCH($A30,Prix!$A$5:$A$79,0)),"") -> 3 | J30: =IF(I30="","",F30*I30) -> 3 | L30: lien
A31: BAT85 | B31: 4. Semi-conducteurs | C31: Diode Schottky BAT85 / BAT43 / BAT42 (DO-35) | D31: D11 | E31: Clamp ADC_VBAT sur +3V3 | F31: 1 | G31: À acheter | H31: =INDEX(Prix!$C$5:$C$79,MATCH($A31,Prix!$A$5:$A$79,0)) -> Moussasoft | I31: =IFERROR(INDEX(Prix!$G$5:$G$79,MATCH($A31,Prix!$A$5:$A$79,0)),"") -> 2 | J31: =IF(I31="","",F31*I31) -> 2 | L31: lien
A32: TVS_6V8 | B32: 4. Semi-conducteurs | C32: Diode TVS 1.5KE6.8A (ou P6KE6.8A) | D32: D12 | E32: TVS 6,8V sur le rail +5V : surtension / inversion résiduelle | F32: 1 | G32: À acheter | H32: =INDEX(Prix!$C$5:$C$79,MATCH($A32,Prix!$A$5:$A$79,0)) -> LCSC | I32: =IFERROR(INDEX(Prix!$G$5:$G$79,MATCH($A32,Prix!$A$5:$A$79,0)),"") | J32: =IF(I32="","",F32*I32) | K32: Protège le rail 5 V. Commander tôt chez LCSC (stock faible). | L32: lien
A33: BC337 | B33: 4. Semi-conducteurs | C33: Transistor NPN BC337-40 (TO-92) | D33: Q8 | E33: Driver gate | F33: 1 | G33: À acheter | H33: =INDEX(Prix!$C$5:$C$79,MATCH($A33,Prix!$A$5:$A$79,0)) -> A2itronic | I33: =IFERROR(INDEX(Prix!$G$5:$G$79,MATCH($A33,Prix!$A$5:$A$79,0)),"") -> 1 | J33: =IF(I33="","",F33*I33) -> 1 | K33: Brochage C-B-E sérigraphié. | L33: lien
A34: IRF4905 | B34: 4. Semi-conducteurs | C34: MOSFET P IRF4905 (TO-220) | D34: Q7, Q12 | E34: P-MOSFET commutation 5V du LDO capteurs; Anti-inversion entrée 5V (P-MOSFET 55V, VGS = -5V | F34: 2 | G34: À acheter | H34: =INDEX(Prix!$C$5:$C$79,MATCH($A34,Prix!$A$5:$A$79,0)) -> A2itronic | I34: =IFERROR(INDEX(Prix!$G$5:$G$79,MATCH($A34,Prix!$A$5:$A$79,0)),"") -> 10 | J34: =IF(I34="","",F34*I34) -> 20 | K34: Respecter la sérigraphie G-D-S de chaque MOSFET. | L34: lien
A35: LD1117 | B35: 4. Semi-conducteurs | C35: Régulateur LD1117V33 TO-220 (1=GND 2=OUT 3=IN) | D35: U1 | E35: Régulateur 3,3V 800mA du rail capteurs (1=GND 2=OUT 3=IN | F35: 1 | G35: À acheter | H35: =INDEX(Prix!$C$5:$C$79,MATCH($A35,Prix!$A$5:$A$79,0)) -> Megma | I35: =IFERROR(INDEX(Prix!$G$5:$G$79,MATCH($A35,Prix!$A$5:$A$79,0)),"") -> 7.5 | J35: =IF(I35="","",F35*I35) -> 7.5 | K35: Ce n'est pas un 78xx : 1=GND 2=OUT 3=IN (sérigraphié). | L35: lien
A36: BORNIER_2P | B36: 6. Connectique carte | C36: Bornier à vis 2 pôles pas 5,08 (KF301-2P) | D36: J1, J12, J18, J19, J25 | E36: Entrée 5V alternative; LDR déportée entre 3V3 et l'ADC; Distribution 5V; Distribution 3V3 capteurs ; … | F36: 5 | G36: À acheter | H36: =INDEX(Prix!$C$5:$C$79,MATCH($A36,Prix!$A$5:$A$79,0)) -> MicroPlanet | I36: =IFERROR(INDEX(Prix!$G$5:$G$79,MATCH($A36,Prix!$A$5:$A$79,0)),"") -> 2 | J36: =IF(I36="","",F36*I36) -> 10 | K36: Entrée du boost 5,1 V. Pont batterie 1S : J25 sur le + de la 18650, JP12 en 2-3. Veille d'urgence firmware ≥ 3,3 V. | L36: lien
A37: BORNIER_3P | B37: 6. Connectique carte | C37: Bornier à vis 3 pôles pas 5,08 (KF301-3P) | D37: J10, J11, J29, J30, J31, J32, J33, J34 | E37: DHT11/DHT22; Sonde DS18B20 étanche; Module pluie DO msp; DHT externe msp ; … | F37: 8 | G37: À acheter | H37: =INDEX(Prix!$C$5:$C$79,MATCH($A37,Prix!$A$5:$A$79,0)) -> MicroPlanet | I37: =IFERROR(INDEX(Prix!$G$5:$G$79,MATCH($A37,Prix!$A$5:$A$79,0)),"") -> 3 | J37: =IF(I37="","",F37*I37) -> 24 | L37: lien
A38: BARRETTE_F | B38: 6. Connectique carte | C38: Barrette femelle sécable 1×40 pas 2,54 | D38: A1 (2×15), J13, J21 | E38: Supports du DevKit (jamais soudé); OLED SSD1306 128x64 I2C 0x3C; Port I2C libre 2 | F38: 2 | G38: À acheter | H38: =INDEX(Prix!$C$5:$C$79,MATCH($A38,Prix!$A$5:$A$79,0)) -> Moussasoft | I38: =IFERROR(INDEX(Prix!$G$5:$G$79,MATCH($A38,Prix!$A$5:$A$79,0)),"") -> 5 | J38: =IF(I38="","",F38*I38) -> 10 | K38: 38 broches femelles utilisées (+ pertes de coupe). | L38: lien
A39: BARRETTE_M | B39: 6. Connectique carte | C39: Barrette mâle sécable 1×40 pas 2,54 | D39: J15, J16, J17, J20, JP1, JP12, JP13, JP14, JP15, JP16, JP17, JP18, JP19, JP20, … | E39: Servo GROS; Servo PETITS; Header service; Rail Dupont ; … | F39: 2 | G39: À acheter | H39: =INDEX(Prix!$C$5:$C$79,MATCH($A39,Prix!$A$5:$A$79,0)) -> Moussasoft | I39: =IFERROR(INDEX(Prix!$G$5:$G$79,MATCH($A39,Prix!$A$5:$A$79,0)),"") -> 4 | J39: =IF(I39="","",F39*I39) -> 8 | K39: 42 broches mâles utilisées (+ pertes de coupe). | L39: lien
A40: CAVALIER | B40: 6. Connectique carte | C40: Cavalier (jumper) 2,54 mm | D40: JP… | E40: Cavaliers de configuration du profil (+2 de rechange) | F40: 9 | G40: À acheter | H40: =INDEX(Prix!$C$5:$C$79,MATCH($A40,Prix!$A$5:$A$79,0)) -> Shop4Makers | I40: =IFERROR(INDEX(Prix!$G$5:$G$79,MATCH($A40,Prix!$A$5:$A$79,0)),"") -> 0.5 | J40: =IF(I40="","",F40*I40) -> 4.5 | K40: Cavaliers posés : JP1 parqué (rail commuté), JP12 en 2-3 (1S), JP16-JP19 et JP21 FERMÉS. | L40: lien
A41: FIL | B41: 6. Connectique carte | C41: Pont de fil à la place de D5 (chute de patte de résistance) | D41: D5 | E41: PONT DE FIL vers VIN DevKit | F41: 1 | G41: À acheter | H41: =INDEX(Prix!$C$5:$C$79,MATCH($A41,Prix!$A$5:$A$79,0)) -> — | I41: =IFERROR(INDEX(Prix!$G$5:$G$79,MATCH($A41,Prix!$A$5:$A$79,0)),"") -> 0 | J41: =IF(I41="","",F41*I41) -> 0 | K41: D5 = pont de fil (rev 0.2.2). Règle absolue : ne JAMAIS brancher l'USB du DevKit quand la carte est alimentée.
A42: TP_FIL | B42: 6. Connectique carte | C42: Points de test TP1-TP4 : boucle de fil (chute de patte) | D42: TP1, TP2, TP3, TP4 | E42: Point de test GND; Point de test +5V; Point de test +3V3_SW; Point de test +3V3 | F42: 4 | G42: À acheter | H42: =INDEX(Prix!$C$5:$C$79,MATCH($A42,Prix!$A$5:$A$79,0)) -> — | I42: =IFERROR(INDEX(Prix!$G$5:$G$79,MATCH($A42,Prix!$A$5:$A$79,0)),"") -> 0 | J42: =IF(I42="","",F42*I42) -> 0
A43: DHT11 | B43: 7. Capteurs et actionneurs | C43: Capteur température/humidité DHT11 | D43: hors carte | E43: Température/humidité air intérieure (J10) et extérieure (J30) | F43: 2 | G43: À acheter | H43: =INDEX(Prix!$C$5:$C$79,MATCH($A43,Prix!$A$5:$A$79,0)) -> Shop4Makers | I43: =IFERROR(INDEX(Prix!$G$5:$G$79,MATCH($A43,Prix!$A$5:$A$79,0)),"") -> 16.2 | J43: =IF(I43="","",F43*I43) -> 32.4 | K43: J30 exige JP21 FERMÉ (pull-up R47). Un BME280 détecté remplace le DHT (option ci-dessous). | L43: lien
A44: BME280 | B44: 7. Capteurs et actionneurs | C44: Module BME280 I2C (température, humidité, pression) | D44: hors carte | E44: Remplace les DHT11 : 0x76 = intérieur, 0x77 = extérieur (I2C J21 / J14) | F44: 2 | G44: Option | H44: =INDEX(Prix!$C$5:$C$79,MATCH($A44,Prix!$A$5:$A$79,0)) -> Shop4Makers | I44: =IFERROR(INDEX(Prix!$G$5:$G$79,MATCH($A44,Prix!$A$5:$A$79,0)),"") -> 85 | J44: =IF(I44="","",F44*I44) -> 170 | K44: Le firmware le détecte au démarrage. Adresse 0x77 : pont SDO à souder sur le module. | L44: lien
...

Sheet n3pp
A1: n3pp — serre (chargeur 5 V)
A2: Carte n3-universal rev 0.2.2 — composants à poser et à acheter pour UNE unité. Prix du 18/10/2026 (feuille Prix). Les quantités (bleu) sont modifiables ; l'achat groupé arrondi aux lots est dans « Global ».
A4: Consignes de pose de ce profil
B5: • Chargeur 5 V 2 A → cordon court et épais → J2 (jack). Jamais par le micro-USB du DevKit.
B6: • JP1 ôté (parqué en 2-3) ; JP12 en 2-3 ; JP20 FERMÉ (LDR) ; JP16-JP19 OUVERTS (sondes de sol) ; JP5 sans cavalier (AUTO).
B7: • Un seul relais : K1 = pompe d'arrosage (et ses pièces Q1, D1, R1, R5, LED1, R9, J3, JP5, R61).
B8: • NE PAS poser : LED5/R13, R43-R46, R17-R19, K2-K6, servos, Hi-Link, section 12 V.
B9: • J25 : relier J25-1 au +5V (J18-1) par un fil, sinon la mesure « batterie » lit 0 et le firmware se met en veille d'urgence (ou clé serveur 112 = 0). À vérifier au premier allumage.
C11: Total à acheter, une unité (DH) | J11: =SUMIFS(J18:J57,G18:G57,"À acheter") -> 929.8
C12: Options (DH) | J12: =SUMIFS(J18:J57,G18:G57,"Option") -> 85
C13: Déjà possédé — valeur indicative (DH) | J13: =SUMIFS(J18:J57,G18:G57,"Déjà possédé") -> 0
C14: Articles à acheter sans prix en ligne (import LCSC, quincaillerie, PCB) | J14: =SUMPRODUCT((G18:G57="À acheter")*(I18:I57="")) -> 3
A17: ID | B17: Catégorie | C17: Article | D17: Réf. carte | E17: Rôle | F17: Qté | G17: Statut | H17: Fournisseur | I17: Prix unitaire (DH) | J17: Coût (DH) | K17: Remarques | L17: Lien
A18: PCB | B18: 1. Carte et cerveau | C18: Circuit imprimé n3-universal rev 0.2.2 (JLCPCB, 2 oz) | D18: — | E18: Circuit imprimé n3-universal rev 0.2.2 | F18: 1 | G18: À acheter | H18: =INDEX(Prix!$C$5:$C$79,MATCH($A18,Prix!$A$5:$A$79,0)) -> JLCPCB | I18: =IFERROR(INDEX(Prix!$G$5:$G$79,MATCH($A18,Prix!$A$5:$A$79,0)),"") | J18: =IF(I18="","",F18*I18) | L18: lien
A19: ESP32_DEVKIT | B19: 1. Carte et cerveau | C19: ESP32 DevKit V1 30 broches (WROOM-32) | D19: A1 | E19: Module ESP32-WROOM-32 DevKit V1 30 broches, sur 2 supports 1x15 | F19: 1 | G19: À acheter | H19: =INDEX(Prix!$C$5:$C$79,MATCH($A19,Prix!$A$5:$A$79,0)) -> Shop4Makers | I19: =IFERROR(INDEX(Prix!$G$5:$G$79,MATCH($A19,Prix!$A$5:$A$79,0)),"") -> 113 | J19: =IF(I19="","",F19*I19) -> 113 | K19: Enfiché sur ses supports, jamais soudé. Vérifier l'écart des rangées (25,4 ou 27,94 mm : support droit sur A ou A'). | L19: lien
A20: R_1k | B20: 2. Résistances | C20: Résistance 1 kΩ 1/4 W | D20: R1, R9, R34, R49, R50, R51, R52, R53, R54, R61 | E20: Résistance base transistor; Résistance LED témoin; Base commande gate; Série ADC_VBAT ; … | F20: 10 | G20: À acheter | H20: =INDEX(Prix!$C$5:$C$79,MATCH($A20,Prix!$A$5:$A$79,0)) -> MicroPlanet | I20: =IFERROR(INDEX(Prix!$G$5:$G$79,MATCH($A20,Prix!$A$5:$A$79,0)),"") -> 0.3 | J20: =IF(I20="","",F20*I20) -> 3 | L20: lien
A21: R_4.7k | B21: 2. Résistances | C21: Résistance 4,7 kΩ 1/4 W | D21: R25, R26 | E21: Pull-up I2C SDA; Pull-up I2C SCL | F21: 2 | G21: À acheter | H21: =INDEX(Prix!$C$5:$C$79,MATCH($A21,Prix!$A$5:$A$79,0)) -> MicroPlanet | I21: =IFERROR(INDEX(Prix!$G$5:$G$79,MATCH($A21,Prix!$A$5:$A$79,0)),"") -> 0.3 | J21: =IF(I21="","",F21*I21) -> 0.6 | L21: lien
A22: R_10k | B22: 2. Résistances | C22: Résistance 10 kΩ 1/4 W | D22: R5, R23, R27, R48 | E22: Pull-down base; Pull-up data DHT11; Bas de pont LDR sur ADC_E; Pull-down base Q8 | F22: 4 | G22: À acheter | H22: =INDEX(Prix!$C$5:$C$79,MATCH($A22,Prix!$A$5:$A$79,0)) -> MicroPlanet | I22: =IFERROR(INDEX(Prix!$G$5:$G$79,MATCH($A22,Prix!$A$5:$A$79,0)),"") -> 0.3 | J22: =IF(I22="","",F22*I22) -> 1.2 | L22: lien
A23: R_18k | B23: 2. Résistances | C23: Résistance 18 kΩ 1/4 W | D23: R39 | E23: Bas du pont VBAT profil bus 12V : 100k/18k | F23: 1 | G23: À acheter | H23: =INDEX(Prix!$C$5:$C$79,MATCH($A23,Prix!$A$5:$A$79,0)) -> MicroPlanet | I23: =IFERROR(INDEX(Prix!$G$5:$G$79,MATCH($A23,Prix!$A$5:$A$79,0)),"") -> 0.3 | J23: =IF(I23="","",F23*I23) -> 0.3 | L23: lien
A24: R_100k | B24: 2. Résistances | C24: Résistance 100 kΩ 1/4 W | D24: R35, R38, R57, R58 | E24: Pull-up grille P-MOSFET vers +5V; Haut du pont VBAT; Grille de Q12 vers GND; Bas du pont VBAT profil 1S : 100k/100k | F24: 4 | G24: À acheter | H24: =INDEX(Prix!$C$5:$C$79,MATCH($A24,Prix!$A$5:$A$79,0)) -> MicroPlanet | I24: =IFERROR(INDEX(Prix!$G$5:$G$79,MATCH($A24,Prix!$A$5:$A$79,0)),"") -> 0.3 | J24: =IF(I24="","",F24*I24) -> 1.2 | L24: lien
A25: C_100n | B25: 3. Condensateurs | C25: Condensateur céramique 100 nF (pas 5 mm) | D25: C3, C4, C6, C7, C8, C9, C10, C13 | E25: Découplage 3V3 capteurs; Découplage 3V3 I2C; Filtre ADC ADC_A; Filtre ADC ADC_B ; … | F25: 8 | G25: À acheter | H25: =INDEX(Prix!$C$5:$C$79,MATCH($A25,Prix!$A$5:$A$79,0)) -> A2itronic | I25: =IFERROR(INDEX(Prix!$G$5:$G$79,MATCH($A25,Prix!$A$5:$A$79,0)),"") -> 0.5 | J25: =IF(I25="","",F25*I25) -> 4 | L25: lien
A26: C_10u25 | B26: 3. Condensateurs | C26: Condensateur électrolytique 10 µF 25 V | D26: C11 | E26: Entrée LDO | F26: 1 | G26: À acheter | H26: =INDEX(Prix!$C$5:$C$79,MATCH($A26,Prix!$A$5:$A$79,0)) -> A2itronic | I26: =IFERROR(INDEX(Prix!$G$5:$G$79,MATCH($A26,Prix!$A$5:$A$79,0)),"") -> 1 | J26: =IF(I26="","",F26*I26) -> 1 | L26: lien
A27: C_100u16 | B27: 3. Condensateurs | C27: Condensateur électrolytique 100 µF 16 V | D27: C12 | E27: Sortie LDO | F27: 1 | G27: À acheter | H27: =INDEX(Prix!$C$5:$C$79,MATCH($A27,Prix!$A$5:$A$79,0)) -> A2itronic | I27: =IFERROR(INDEX(Prix!$G$5:$G$79,MATCH($A27,Prix!$A$5:$A$79,0)),"") -> 1 | J27: =IF(I27="","",F27*I27) -> 1 | L27: lien
A28: C_1000u16 | B28: 3. Condensateurs | C28: Condensateur électrolytique 1000 µF 16 V (diam. 10 mm) | D28: C1 | E28: Réservoir rail 5V | F28: 1 | G28: À acheter | H28: =INDEX(Prix!$C$5:$C$79,MATCH($A28,Prix!$A$5:$A$79,0)) -> A2itronic | I28: =IFERROR(INDEX(Prix!$G$5:$G$79,MATCH($A28,Prix!$A$5:$A$79,0)),"") -> 3 | J28: =IF(I28="","",F28*I28) -> 3 | L28: lien
A29: 1N4007 | B29: 4. Semi-conducteurs | C29: Diode 1N4007 (roue libre des bobines de relais) | D29: D1 | E29: Diode de roue libre bobine | F29: 1 | G29: À acheter | H29: =INDEX(Prix!$C$5:$C$79,MATCH($A29,Prix!$A$5:$A$79,0)) -> Shop4Makers | I29: =IFERROR(INDEX(Prix!$G$5:$G$79,MATCH($A29,Prix!$A$5:$A$79,0)),"") -> 0.9 | J29: =IF(I29="","",F29*I29) -> 0.9 | L29: lien
A30: BAT85 | B30: 4. Semi-conducteurs | C30: Diode Schottky BAT85 / BAT43 / BAT42 (DO-35) | D30: D11 | E30: Clamp ADC_VBAT sur +3V3 | F30: 1 | G30: À acheter | H30: =INDEX(Prix!$C$5:$C$79,MATCH($A30,Prix!$A$5:$A$79,0)) -> Moussasoft | I30: =IFERROR(INDEX(Prix!$G$5:$G$79,MATCH($A30,Prix!$A$5:$A$79,0)),"") -> 2 | J30: =IF(I30="","",F30*I30) -> 2 | L30: lien
